Workbook
Name Slicer_Athlete: #N/A
Name Slicer_Category: #N/A
Name Slicer_Client: #N/A
Name Slicer_Month: #N/A
Name Slicer_Subcategory: #N/A
Name Slicer_Year: #N/A

Sheet Raw_Data
A1: FECHA | B1: Year | C1: CONCEPTO | D1: DEPORTISTA | E1: CLIENTE | F1: CUENTA (IN) | G1: CUENTA (OUT) | H1: VALOR (IN) | I1: VALOR (OUT) | J1: SALDO EFECTIVO | K1: FACTURA | L1: OBSERVACIONES | M1: SourceFile | N1: DIA
A2: 43831 | B2: 2020 | C2: Saldo Inicial En Caja | F2: Efectivo | G2: Utilidad Del Ejercicio 2019 | H2: 1870000 | I2: -1870000 | J2: 1870000 | M2: 2020-2 Contabilidad Tornado.xlsx | N2: 43831
A3: 43831 | B3: 2020 | F3: Utilidad Del Ejercicio 2020 | G3: Ajustes | H3: 1177020 | I3: -1177020 | J3: 1870000 | M3: 2020-2 Contabilidad Tornado.xlsx | N3: 43831
A4: 43831 | B4: 2020 | F4: Implementacion Deportiva | G4: Capital Social | H4: 415000 | I4: -415000 | J4: 1870000 | M4: 2020-2 Contabilidad Tornado.xlsx | N4: 43831
A5: 43831 | B5: 2020 | C5: CxC 2019 | D5: Jacobo Zea Osorio | E5: Luis Fernando Zea Sanabria | F5: CxC | G5: Utilidad Del Ejercicio 2019 | H5: 160000 | I5: -160000 | J5: 1870000 | M5: 2020-2 Contabilidad Tornado.xlsx | N5: 43831
A6: 43832 | B6: 2020 | C6: Becas Resultados 2019 (100%) (ENE) | D6: Alejandro Solarte Osorio | E6: Luis Eduardo Solarte Serna | F6: Becas | G6: Mensualidad | H6: 150000 | I6: -150000 | J6: 1870000 | M6: 2020-2 Contabilidad Tornado.xlsx | N6: 43832
A7: 43832 | B7: 2020 | C7: Pago Matricula 100% | D7: Alejandro Solarte Osorio | E7: Luis Eduardo Solarte Serna | F7: Efectivo | G7: Matricula | H7: 100000 | I7: -100000 | J7: 1970000 | M7: 2020-2 Contabilidad Tornado.xlsx | N7: 43832
A8: 43832 | B8: 2020 | C8: Beca 2do Hermanos (20%) (ENE) | D8: Jacobo Zea Osorio | E8: Luis Fernando Zea Sanabria | F8: Becas | G8: Mensualidad | H8: 20000 | I8: -20000 | J8: 1970000 | M8: 2020-2 Contabilidad Tornado.xlsx | N8: 43832
A9: 43832 | B9: 2020 | C9: Pago Matricula 100% | D9: Jacobo Zea Osorio | E9: Luis Fernando Zea Sanabria | F9: Efectivo | G9: Matricula | H9: 100000 | I9: -100000 | J9: 2070000 | M9: 2020-2 Contabilidad Tornado.xlsx | N9: 43832
A10: 43832 | B10: 2020 | C10: Pago Mensualidad (ENE) | D10: Jacobo Zea Osorio | E10: Luis Fernando Zea Sanabria | F10: Efectivo | G10: Mensualidad | H10: 80000 | I10: -80000 | J10: 2150000 | M10: 2020-2 Contabilidad Tornado.xlsx | N10: 43832
A11: 43832 | B11: 2020 | C11: Becas Resultados 2019 (100%) (ENE) | D11: Juan Camilo Osorio Mendoza | E11: Omar Osorio Valencia | F11: Becas | G11: Mensualidad | H11: 150000 | I11: -150000 | J11: 2150000 | M11: 2020-2 Contabilidad Tornado.xlsx | N11: 43832
A12: 43832 | B12: 2020 | C12: Apoyo Gimnasio (Crossfit) (ENE) | D12: Juan Manuel Duque Pinto | E12: Víctor Manuel Duque Yepes | F12: Efectivo | G12: Apoyo Deportistas | H12: -50000 | I12: 50000 | J12: 2100000 | M12: 2020-2 Contabilidad Tornado.xlsx | N12: 43832
A13: 43832 | B13: 2020 | C13: Pago Matricula 100% | D13: Juan Manuel Duque Pinto | E13: Víctor Manuel Duque Yepes | F13: Efectivo | G13: Matricula | H13: 100000 | I13: -100000 | J13: 2200000 | M13: 2020-2 Contabilidad Tornado.xlsx | N13: 43832
A14: 43832 | B14: 2020 | C14: Pago Mensualidad (ENE) | D14: Juan Manuel Duque Pinto | E14: Víctor Manuel Duque Yepes | F14: Efectivo | G14: Mensualidad | H14: 150000 | I14: -150000 | J14: 2350000 | M14: 2020-2 Contabilidad Tornado.xlsx | N14: 43832
A15: 43832 | B15: 2020 | C15: Pago Matricula 100% | D15: Luciana Pinedo Torres | E15: Silvana Torres López | F15: Efectivo | G15: Matricula | H15: 100000 | I15: -100000 | J15: 2450000 | M15: 2020-2 Contabilidad Tornado.xlsx | N15: 43832
A16: 43832 | B16: 2020 | C16: Pago Matricula 100% | D16: Martin Pinzón Correa | E16: Katherine Correa Muñoz | F16: Efectivo | G16: Matricula | H16: 100000 | I16: -100000 | J16: 2550000 | M16: 2020-2 Contabilidad Tornado.xlsx | N16: 43832
... A21: 43832 | B21: 2020 | C21: Pago Matricula 100% | D21: Juan Camilo Osorio Mendoza | E21: Omar Osorio Valencia | F21: Efectivo | G21: Matricula | H21: 100000 | I21: -100000 | J21: 2950000 | M21: 2020-2 Contabilidad Tornado.xlsx | N21: 43832
A22: 43832 | B22: 2020 | C22: Afiliacion Anual Liga 2020 (LINAVALLE) | F22: Efectivo | G22: Arriendos | H22: -878000 | I22: 878000 | J22: 2072000 | M22: 2020-2 Contabilidad Tornado.xlsx | N22: 43832
A23: 43861 | B23: 2020 | C23: Pago Nomina (ENE) | D23: Tiffany Santamaría Escobar | E23: Tiffany Santamaría Escobar | F23: Efectivo | G23: Nomina | H23: -300000 | I23: 300000 | J23: 1772000 | M23: 2020-2 Contabilidad Tornado.xlsx | N23: 43861
A24: 43862 | B24: 2020 | C24: Becas Resultados 2019 (100%) (FEB) | D24: Alejandro Solarte Osorio | E24: Luis Eduardo Solarte Serna | F24: Becas | G24: Mensualidad | H24: 150000 | I24: -150000 | J24: 1772000 | M24: 2020-2 Contabilidad Tornado.xlsx | N24: 43862
A25: 43862 | B25: 2020 | C25: Abono Mensualidad (FEB) | D25: Jacobo Zea Osorio | E25: Luis Fernando Zea Sanabria | F25: Efectivo | G25: Mensualidad | H25: 20000 | I25: -20000 | J25: 1792000 | M25: 2020-2 Contabilidad Tornado.xlsx | N25: 43862
A26: 43862 | B26: 2020 | C26: Beca 2do Hermanos (20%) (FEB) | D26: Jacobo Zea Osorio | E26: Luis Fernando Zea Sanabria | F26: Becas | G26: Mensualidad | H26: 20000 | I26: -20000 | J26: 1792000 | M26: 2020-2 Contabilidad Tornado.xlsx | N26: 43862
A27: 43862 | B27: 2020 | C27: Pago Mensualidad (FEB) | D27: jacobo Zea Osorio | E27: Luis Fernando Zea Sanabria | F27: Efectivo | G27: Mensualidad | H27: 60000 | I27: -60000 | J27: 1852000 | M27: 2020-2 Contabilidad Tornado.xlsx | N27: 43862
A28: 43862 | B28: 2020 | C28: Pago Mensualidad (NOV,DIC 2019) (CxC) | D28: Jacobo Zea Osorio | E28: Luis Fernando Zea Sanabria | F28: Efectivo | G28: CxC | H28: 160000 | I28: -160000 | J28: 2012000 | M28: 2020-2 Contabilidad Tornado.xlsx | N28: 43862
A29: 43862 | B29: 2020 | C29: Becas Resultados 2019 (100%) (FEB) | D29: Juan Camilo Osorio Mendoza | E29: Omar Osorio Valencia | F29: Becas | G29: Mensualidad | H29: 150000 | I29: -150000 | J29: 2012000 | M29: 2020-2 Contabilidad Tornado.xlsx | N29: 43862
A30: 43862 | B30: 2020 | C30: Pago Mensualidad (FEB) | D30: Juan Manuel Duque Pinto | E30: Víctor Manuel Duque Yepes | F30: Efectivo | G30: Mensualidad | H30: 150000 | I30: -150000 | J30: 2162000 | M30: 2020-2 Contabilidad Tornado.xlsx | N30: 43862
A31: 43862 | B31: 2020 | C31: Beca 2do Hermanos (20%) (FEB) | D31: Luciana Pinedo Torres | E31: Silvana Torres López | F31: Becas | G31: Mensualidad | H31: 20000 | I31: -20000 | J31: 2162000 | M31: 2020-2 Contabilidad Tornado.xlsx | N31: 43862
A32: 43862 | B32: 2020 | C32: Pago Mensualidad (FEB) | D32: Luciana Pinedo Torres | E32: Silvana Torres López | F32: Efectivo | G32: Mensualidad | H32: 80000 | I32: -80000 | J32: 2242000 | M32: 2020-2 Contabilidad Tornado.xlsx | N32: 43862
A33: 43862 | B33: 2020 | C33: Pago Mensualidad (FEB) | D33: Martin Pinzón Correa | E33: Katherine Correa Muñoz | F33: Efectivo | G33: Mensualidad | H33: 100000 | I33: -100000 | J33: 2342000 | M33: 2020-2 Contabilidad Tornado.xlsx | N33: 43862
A34: 43862 | B34: 2020 | C34: Pago Mensualidad (FEB) | D34: Sofía Gómez Torres | E34: Nelson Gómez Serna | F34: Efectivo | G34: Mensualidad | H34: 100000 | I34: -100000 | J34: 2442000 | M34: 2020-2 Contabilidad Tornado.xlsx | N34: 43862
A35: 43862 | B35: 2020 | C35: Becas Resultados 2019 (100%) (FEB) | D35: Valentina Quintero Torres | E35: Silvana Torres López | F35: Becas | G35: Mensualidad | H35: 150000 | I35: -150000 | J35: 2442000 | M35: 2020-2 Contabilidad Tornado.xlsx | N35: 43862
A36: 43862 | B36: 2020 | C36: Abono a Compra de Uniformes (GIMAO) | F36: Efectivo | G36: Uniformes | H36: -500000 | I36: 500000 | J36: 1942000 | M36: 2020-2 Contabilidad Tornado.xlsx | N36: 43862
A37: 43862 | B37: 2020 | C37: Compra de 1000 Volantes Publicitarios | F37: Efectivo | G37: Publicidad | H37: -135000 | I37: 135000 | J37: 1807000 | M37: 2020-2 Contabilidad Tornado.xlsx | N37: 43862
A38: 43862 | B38: 2020 | C38: Compra de Espadadrapo | F38: Efectivo | G38: Otros Gastos Deportivos | H38: -60000 | I38: 60000 | J38: 1747000 | M38: 2020-2 Contabilidad Tornado.xlsx | N38: 43862
A39: 43862 | B39: 2020 | C39: Compra de Hielo para Recuperacion | F39: Efectivo | G39: Otros Gastos Deportivos | H39: -23000 | I39: 23000 | J39: 1724000 | M39: 2020-2 Contabilidad Tornado.xlsx | N39: 43862
A40: 43862 | B40: 2020 | C40: Compra Postres para Deportistas (Medellin Chequeo) | F40: Efectivo | G40: Otros Gastos | H40: -37000 | I40: 37000 | J40: 1687000 | M40: 2020-2 Contabilidad Tornado.xlsx | N40: 43862
A41: 43862 | B41: 2020 | C41: Parqueadero y Estampillas Certificado (SEC DEP) | F41: Efectivo | G41: Otros Gastos | H41: -16500 | I41: 16500 | J41: 1670500 | M41: 2020-2 Contabilidad Tornado.xlsx | N41: 43862
A42: 43890 | B42: 2020 | C42: Pago Nomina (FEB) | D42: Tiffany Santamaría Escobar | E42: Tiffany Santamaría Escobar | F42: Efectivo | G42: Nomina | H42: -300000 | I42: 300000 | J42: 1370500 | M42: 2020-2 Contabilidad Tornado.xlsx | N42: 43890
A43: 43891 | B43: 2020 | C43: Apoyo Ficha Fecna (3) y Seguros (5) 2020 | F43: Efectivo | G43: Apoyo Deportistas | H43: -345000 | I43: 345000 | J43: 1025500 | M43: 2020-2 Contabilidad Tornado.xlsx | N43: 43891
A44: 43892 | B44: 2020 | C44: Becas Resultados 2019 (100%) (MAR) | D44: Alejandro Solarte Osorio | E44: Luis Eduardo Solarte Serna | F44: Becas | G44: Mensualidad | H44: 75000 | I44: -75000 | J44: 1025500 | L44: Se cobra la mitad de la mensualidad por cierre de escenarios deportivos | M44: 2020-2 Contabilidad Tornado.xlsx | N44: 43892
...

Sheet Extra_Data
B3: CUENTA_IN | C3: Category | D3: CUENTA_OUT | E3: Subcategory
B4: Efectivo | C4: Cash | D4: Matricula | E4: Enrollment Fees
B5: Implementacion Deportiva | C5: Sports Equipment | D5: Mensualidad | E5: Monthly Fee
B6: CxC | C6: Accounts Receivable | D6: Mensualidad Gimnasia | E6: Gymnastics Monthly Fee
B7: Becas | C7: Scholarships | D7: CxC | E7: Accounts Receivable
B8: Uniformes | C8: Uniform Sales | D8: Arriendos | E8: Rent
B9: Descuentos | C9: Adjustments | D9: Nomina | E9: Payroll
B10: Utilidad Del Ejercicio 2019 | C10: Profit 2019 | D10: Apoyo Deportistas | E10: Athlete Support
B11: Utilidad Del Ejercicio 2020 | C11: Profit 2020 | D11: Apoyo Entrenadores | E11: Coach Support
B12: Utilidad Del Ejercicio 2021 | C12: Profit 2021 | D12: Implementacion Deportiva | E12: Sports Equipment
B13: Utilidad Del Ejercicio 2022 | C13: Profit 2022 | D13: Uniformes | E13: Uniforms
B14: Utilidad Del Ejercicio 2023 | C14: Profit 2023 | D14: Publicidad | E14: Advertising
... B22: CxP (Terceros) | C22: Accounts Payable – Third Parties | D22: Efectivo | E22: Cash
D23: Becas | E23: Scholarships
D24: Descuentos | E24: Adjustments
D25: Utilidad Del Ejercicio 2019 | E25: Profit 2019
D26: Utilidad Del Ejercicio 2020 | E26: Profit 2020
D27: Utilidad Del Ejercicio 2021 | E27: Profit 2021
D28: Utilidad Del Ejercicio 2022 | E28: Profit 2022
D29: Utilidad Del Ejercicio 2023 | E29: Profit 2023
D30: Utilidad Del Ejercicio 2024 | E30: Profit 2024
D31: Utilidad Del Ejercicio 2025 | E31: Profit 2025
D32: Utilidad Acumulada 2022 | E32: Retained Earnings 2022
D33: Utilidad Acumulada 2023 | E33: Retained Earnings 2023
D34: Utilidad Acumulada 2024 | E34: Retained Earnings 2024
... D40: CxP (Liga) | E40: Accounts Payable – League
D44: Matricula
D45: Mensualidad
D46: Mensualidad Gimnasia
D47: CxC
D48: Arriendos
D49: Nomina
D50: Apoyo Deportistas
D51: Apoyo Entrenadores
D52: Implementacion Deportiva
D53: Uniformes
D54: Publicidad
D55: Otros Gastos Deportivos
... D61: CxP
D62: 0
...

Sheet Clean_Data
A1: Date | B1: Year | C1: Month | D1: Type | E1: Category | F1: Subcategory | G1: Description | H1: Amount | I1: Method | J1: Account | K1: Client | L1: Athlete | M1: Cash Flag | N1: Cash Amount | O1: AR_Flag | P1: AR_Amount | Q1: AP_Flag | R1: AP_Amount
A2: =FIN_RAW[[#This Row],[FECHA]] -> 43831 | B2: =YEAR(FIN_DATASET[[#This Row],[Date]]) -> 2020 | C2: =TEXT(FIN_DATASET[[#This Row],[Date]],"mmmm") -> January | D2: =IF(FIN_RAW[[#This Row],[VALOR (IN)]]>0, "Income",IF(FIN_RAW[[#This Row],[VALOR (OUT)]]>0, "Expense", "Check")) -> Income | E2: =_xlfn.XLOOKUP(FIN_DATASET[[#This Row],[Method]],CATEGORY_MAP[CUENTA_IN],CATEGORY_MAP[Category]) -> Cash | F2: =_xlfn.XLOOKUP(FIN_DATASET[[#This Row],[Account]],CATEGORY_MAP[CUENTA_OUT],CATEGORY_MAP[Subcategory]) -> Profit 2019 | G2: =IF(OR(FIN_RAW[[#This Row],[CONCEPTO]]=0,FIN_RAW[[#This Row],[CONCEPTO]]=""),"",FIN_RAW[[#This Row],[CONCEPTO]]) -> Saldo Inicial En Caja | H2: =IF(FIN_DATASET[[#This Row],[Type]]="Income", FIN_RAW[[#This Row],[VALOR (IN)]], -FIN_RAW[[#This Row],[VALOR (OUT)]]) -> 1870000 | I2: =FIN_RAW[[#This Row],[CUENTA (IN)]] -> Efectivo | J2: =FIN_RAW[[#This Row],[CUENTA (OUT)]] -> Utilidad Del Ejercicio 2019 | K2: =IF(OR(FIN_RAW[[#This Row],[CLIENTE]]=0,FIN_RAW[[#This Row],[CLIENTE]]=" "),"",FIN_RAW[[#This Row],[CLIENTE]]) | L2: =IF(OR(FIN_RAW[[#This Row],[DEPORTISTA]]=0,FIN_RAW[[#This Row],[DEPORTISTA]]=""),"",FIN_RAW[[#This Row],[DEPORTISTA]]) | M2: =IF(FIN_DATASET[[#This Row],[Method]]="Efectivo",1,0) -> 1 | N2: =IF(FIN_DATASET[[#This Row],[Method]]="Efectivo",FIN_DATASET[[#This Row],[Amount]],0) -> 1870000 | O2: =IF(FIN_DATASET[[#This Row],[Method]]="CxC",1,0) -> 0 | P2: =IF(FIN_DATASET[[#This Row],[Method]]="CxC",FIN_DATASET[[#This Row],[Amount]],0) -> 0 | Q2: =IF(OR(FIN_DATASET[[#This Row],[Account]]="CxP",FIN_DATASET[[#This Row],[Account]]="CxP (Liga)",FIN_DATASET[[#This Row],[Account]]="CxP (Terceros)"),1,0) -> 0 | R2: =IF(FIN_DATASET[[#This Row],[AP_Flag]]=1,FIN_DATASET[[#This Row],[Amount]],0) -> 0
A3: =FIN_RAW[[#This Row],[FECHA]] -> 43831 | B3: =YEAR(FIN_DATASET[[#This Row],[Date]]) -> 2020 | C3: =TEXT(FIN_DATASET[[#This Row],[Date]],"mmmm") -> January | D3: =IF(FIN_RAW[[#This Row],[VALOR (IN)]]>0, "Income",IF(FIN_RAW[[#This Row],[VALOR (OUT)]]>0, "Expense", "Check")) -> Income | E3: =_xlfn.XLOOKUP(FIN_DATASET[[#This Row],[Method]],CATEGORY_MAP[CUENTA_IN],CATEGORY_MAP[Category]) -> Profit 2020 | F3: =_xlfn.XLOOKUP(FIN_DATASET[[#This Row],[Account]],CATEGORY_MAP[CUENTA_OUT],CATEGORY_MAP[Subcategory]) -> Account Adjustments | G3: =IF(OR(FIN_RAW[[#This Row],[CONCEPTO]]=0,FIN_RAW[[#This Row],[CONCEPTO]]=""),"",FIN_RAW[[#This Row],[CONCEPTO]]) | H3: =IF(FIN_DATASET[[#This Row],[Type]]="Income", FIN_RAW[[#This Row],[VALOR (IN)]], -FIN_RAW[[#This Row],[VALOR (OUT)]]) -> 1177020 | I3: =FIN_RAW[[#This Row],[CUENTA (IN)]] -> Utilidad Del Ejercicio 2020 | J3: =FIN_RAW[[#This Row],[CUENTA (OUT)]] -> Ajustes | K3: =IF(OR(FIN_RAW[[#This Row],[CLIENTE]]=0,FIN_RAW[[#This Row],[CLIENTE]]=" "),"",FIN_RAW[[#This Row],[CLIENTE]]) | L3: =IF(OR(FIN_RAW[[#This Row],[DEPORTISTA]]=0,FIN_RAW[[#This Row],[DEPORTISTA]]=""),"",FIN_RAW[[#This Row],[DEPORTISTA]]) | M3: =IF(FIN_DATASET[[#This Row],[Method]]="Efectivo",1,0) -> 0 | N3: =IF(FIN_DATASET[[#This Row],[Method]]="Efectivo",FIN_DATASET[[#This Row],[Amount]],0) -> 0 | O3: =IF(FIN_DATASET[[#This Row],[Method]]="CxC",1,0) -> 0 | P3: =IF(FIN_DATASET[[#This Row],[Method]]="CxC",FIN_DATASET[[#This Row],[Amount]],0) -> 0 | Q3: =IF(OR(FIN_DATASET[[#This Row],[Account]]="CxP",FIN_DATASET[[#This Row],[Account]]="CxP (Liga)",FIN_DATASET[[#This Row],[Account]]="CxP (Terceros)"),1,0) -> 0 | R3: =IF(FIN_DATASET[[#This Row],[AP_Flag]]=1,FIN_DATASET[[#This Row],[Amount]],0) -> 0
A4: =FIN_RAW[[#This Row],[FECHA]] -> 43831 | B4: =YEAR(FIN_DATASET[[#This Row],[Date]]) -> 2020 | C4: =TEXT(FIN_DATASET[[#This Row],[Date]],"mmmm") -> January | D4: =IF(FIN_RAW[[#This Row],[VALOR (IN)]]>0, "Income",IF(FIN_RAW[[#This Row],[VALOR (OUT)]]>0, "Expense", "Check")) -> Income | E4: =_xlfn.XLOOKUP(FIN_DATASET[[#This Row],[Method]],CATEGORY_MAP[CUENTA_IN],CATEGORY_MAP[Category]) -> Sports Equipment | F4: =_xlfn.XLOOKUP(FIN_DATASET[[#This Row],[Account]],CATEGORY_MAP[CUENTA_OUT],CATEGORY_MAP[Subcategory]) -> Capital | G4: =IF(OR(FIN_RAW[[#This Row],[CONCEPTO]]=0,FIN_RAW[[#This Row],[CONCEPTO]]=""),"",FIN_RAW[[#This Row],[CONCEPTO]]) | H4: =IF(FIN_DATASET[[#This Row],[Type]]="Income", FIN_RAW[[#This Row],[VALOR (IN)]], -FIN_RAW[[#This Row],[VALOR (OUT)]]) -> 415000 | I4: =FIN_RAW[[#This Row],[CUENTA (IN)]] -> Implementacion Deportiva | J4: =FIN_RAW[[#This Row],[CUENTA (OUT)]] -> Capital Social | K4: =IF(OR(FIN_RAW[[#This Row],[CLIENTE]]=0,FIN_RAW[[#This Row],[CLIENTE]]=" "),"",FIN_RAW[[#This Row],[CLIENTE]]) | L4: =IF(OR(FIN_RAW[[#This Row],[DEPORTISTA]]=0,FIN_RAW[[#This Row],[DEPORTISTA]]=""),"",FIN_RAW[[#This Row],[DEPORTISTA]]) | M4: =IF(FIN_DATASET[[#This Row],[Method]]="Efectivo",1,0) -> 0 | N4: =IF(FIN_DATASET[[#This Row],[Method]]="Efectivo",FIN_DATASET[[#This Row],[Amount]],0) -> 0 | O4: =IF(FIN_DATASET[[#This Row],[Method]]="CxC",1,0) -> 0 | P4: =IF(FIN_DATASET[[#This Row],[Method]]="CxC",FIN_DATASET[[#This Row],[Amount]],0) -> 0 | Q4: =IF(OR(FIN_DATASET[[#This Row],[Account]]="CxP",FIN_DATASET[[#This Row],[Account]]="CxP (Liga)",FIN_DATASET[[#This Row],[Account]]="CxP (Terceros)"),1,0) -> 0 | R4: =IF(FIN_DATASET[[#This Row],[AP_Flag]]=1,FIN_DATASET[[#This Row],[Amount]],0) -> 0
A5: =FIN_RAW[[#This Row],[FECHA]] -> 43831 | B5: =YEAR(FIN_DATASET[[#This Row],[Date]]) -> 2020 | C5: =TEXT(FIN_DATASET[[#This Row],[Date]],"mmmm") -> January | D5: =IF(FIN_RAW[[#This Row],[VALOR (IN)]]>0, "Income",IF(FIN_RAW[[#This Row],[VALOR (OUT)]]>0, "Expense", "Check")) -> Income | E5: =_xlfn.XLOOKUP(FIN_DATASET[[#This Row],[Method]],CATEGORY_MAP[CUENTA_IN],CATEGORY_MAP[Category]) -> Accounts Receivable | F5: =_xlfn.XLOOKUP(FIN_DATASET[[#This Row],[Account]],CATEGORY_MAP[CUENTA_OUT],CATEGORY_MAP[Subcategory]) -> Profit 2019 | G5: =IF(OR(FIN_RAW[[#This Row],[CONCEPTO]]=0,FIN_RAW[[#This Row],[CONCEPTO]]=""),"",FIN_RAW[[#This Row],[CONCEPTO]]) -> CxC 2019 | H5: =IF(FIN_DATASET[[#This Row],[Type]]="Income", FIN_RAW[[#This Row],[VALOR (IN)]], -FIN_RAW[[#This Row],[VALOR (OUT)]]) -> 160000 | I5: =FIN_RAW[[#This Row],[CUENTA (IN)]] -> CxC | J5: =FIN_RAW[[#This Row],[CUENTA (OUT)]] -> Utilidad Del Ejercicio 2019 | K5: =IF(OR(FIN_RAW[[#This Row],[CLIENTE]]=0,FIN_RAW[[#This Row],[CLIENTE]]=" "),"",FIN_RAW[[#This Row],[CLIENTE]]) -> Luis Fernando Zea Sanabria | L5: =IF(OR(FIN_RAW[[#This Row],[DEPORTISTA]]=0,FIN_RAW[[#This Row],[DEPORTISTA]]=""),"",FIN_RAW[[#This Row],[DEPORTISTA]]) -> Jacobo Zea Osorio | M5: =IF(FIN_DATASET[[#This Row],[Method]]="Efectivo",1,0) -> 0 | N5: =IF(FIN_DATASET[[#This Row],[Method]]="Efectivo",FIN_DATASET[[#This Row],[Amount]],0) -> 0 | O5: =IF(FIN_DATASET[[#This Row],[Method]]="CxC",1,0) -> 1 | P5: =IF(FIN_DATASET[[#This Row],[Method]]="CxC",FIN_DATASET[[#This Row],[Amount]],0) -> 160000 | Q5: =IF(OR(FIN_DATASET[[#This Row],[Account]]="CxP",FIN_DATASET[[#This Row],[Account]]="CxP (Liga)",FIN_DATASET[[#This Row],[Account]]="CxP (Terceros)"),1,0) -> 0 | R5: =IF(FIN_DATASET[[#This Row],[AP_Flag]]=1,FIN_DATASET[[#This Row],[Amount]],0) -> 0
A6: =FIN_RAW[[#This Row],[FECHA]] -> 43832 | B6: =YEAR(FIN_DATASET[[#This Row],[Date]]) -> 2020 | C6: =TEXT(FIN_DATASET[[#This Row],[Date]],"mmmm") -> January | D6: =IF(FIN_RAW[[#This Row],[VALOR (IN)]]>0, "Income",IF(FIN_RAW[[#This Row],[VALOR (OUT)]]>0, "Expense", "Check")) -> Income | E6: =_xlfn.XLOOKUP(FIN_DATASET[[#This Row],[Method]],CATEGORY_MAP[CUENTA_IN],CATEGORY_MAP[Category]) -> Scholarships | F6: =_xlfn.XLOOKUP(FIN_DATASET[[#This Row],[Account]],CATEGORY_MAP[CUENTA_OUT],CATEGORY_MAP[Subcategory]) -> Monthly Fee | G6: =IF(OR(FIN_RAW[[#This Row],[CONCEPTO]]=0,FIN_RAW[[#This Row],[CONCEPTO]]=""),"",FIN_RAW[[#This Row],[CONCEPTO]]) -> Becas Resultados 2019 (100%) (ENE) | H6: =IF(FIN_DATASET[[#This Row],[Type]]="Income", FIN_RAW[[#This Row],[VALOR (IN)]], -FIN_RAW[[#This Row],[VALOR (OUT)]]) -> 150000 | I6: =FIN_RAW[[#This Row],[CUENTA (IN)]] -> Becas | J6: =FIN_RAW[[#This Row],[CUENTA (OUT)]] -> Mensualidad | K6: =IF(OR(FIN_RAW[[#This Row],[CLIENTE]]=0,FIN_RAW[[#This Row],[CLIENTE]]=" "),"",FIN_RAW[[#This Row],[CLIENTE]]) -> Luis Eduardo Solarte Serna | L6: =IF(OR(FIN_RAW[[#This Row],[DEPORTISTA]]=0,FIN_RAW[[#This Row],[DEPORTISTA]]=""),"",FIN_RAW[[#This Row],[DEPORTISTA]]) -> Alejandro Solarte Osorio | M6: =IF(FIN_DATASET[[#This Row],[Method]]="Efectivo",1,0) -> 0 | N6: =IF(FIN_DATASET[[#This Row],[Method]]="Efectivo",FIN_DATASET[[#This Row],[Amount]],0) -> 0 | O6: =IF(FIN_DATASET[[#This Row],[Method]]="CxC",1,0) -> 0 | P6: =IF(FIN_DATASET[[#This Row],[Method]]="CxC",FIN_DATASET[[#This Row],[Amount]],0) -> 0 | Q6: =IF(OR(FIN_DATASET[[#This Row],[Account]]="CxP",FIN_DATASET[[#This Row],[Account]]="CxP (Liga)",FIN_DATASET[[#This Row],[Account]]="CxP (Terceros)"),1,0) -> 0 | R6: =IF(FIN_DATASET[[#This Row],[AP_Flag]]=1,FIN_DATASET[[#This Row],[Amount]],0) -> 0
A7: =FIN_RAW[[#This Row],[FECHA]] -> 43832 | B7: =YEAR(FIN_DATASET[[#This Row],[Date]]) -> 2020 | C7: =TEXT(FIN_DATASET[[#This Row],[Date]],"mmmm") -> January | D7: =IF(FIN_RAW[[#This Row],[VALOR (IN)]]>0, "Income",IF(FIN_RAW[[#This Row],[VALOR (OUT)]]>0, "Expense", "Check")) -> Income | E7: =_xlfn.XLOOKUP(FIN_DATASET[[#This Row],[Method]],CATEGORY_MAP[CUENTA_IN],CATEGORY_MAP[Category]) -> Cash | F7: =_xlfn.XLOOKUP(FIN_DATASET[[#This Row],[Account]],CATEGORY_MAP[CUENTA_OUT],CATEGORY_MAP[Subcategory]) -> Enrollment Fees | G7: =IF(OR(FIN_RAW[[#This Row],[CONCEPTO]]=0,FIN_RAW[[#This Row],[CONCEPTO]]=""),"",FIN_RAW[[#This Row],[CONCEPTO]]) -> Pago Matricula 100% | H7: =IF(FIN_DATASET[[#This Row],[Type]]="Income", FIN_RAW[[#This Row],[VALOR (IN)]], -FIN_RAW[[#This Row],[VALOR (OUT)]]) -> 100000 | I7: =FIN_RAW[[#This Row],[CUENTA (IN)]] -> Efectivo | J7: =FIN_RAW[[#This Row],[CUENTA (OUT)]] -> Matricula | K7: =IF(OR(FIN_RAW[[#This Row],[CLIENTE]]=0,FIN_RAW[[#This Row],[CLIENTE]]=" "),"",FIN_RAW[[#This Row],[CLIENTE]]) -> Luis Eduardo Solarte Serna | L7: =IF(OR(FIN_RAW[[#This Row],[DEPORTISTA]]=0,FIN_RAW[[#This Row],[DEPORTISTA]]=""),"",FIN_RAW[[#This Row],[DEPORTISTA]]) -> Alejandro Solarte Osorio | M7: =IF(FIN_DATASET[[#This Row],[Method]]="Efectivo",1,0) -> 1 | N7: =IF(FIN_DATASET[[#This Row],[Method]]="Efectivo",FIN_DATASET[[#This Row],[Amount]],0) -> 100000 | O7: =IF(FIN_DATASET[[#This Row],[Method]]="CxC",1,0) -> 0 | P7: =IF(FIN_DATASET[[#This Row],[Method]]="CxC",FIN_DATASET[[#This Row],[Amount]],0) -> 0 | Q7: =IF(OR(FIN_DATASET[[#This Row],[Account]]="CxP",FIN_DATASET[[#This Row],[Account]]="CxP (Liga)",FIN_DATASET[[#This Row],[Account]]="CxP (Terceros)"),1,0) -> 0 | R7: =IF(FIN_DATASET[[#This Row],[AP_Flag]]=1,FIN_DATASET[[#This Row],[Amount]],0) -> 0
A8: =FIN_RAW[[#This Row],[FECHA]] -> 43832 | B8: =YEAR(FIN_DATASET[[#This Row],[Date]]) -> 2020 | C8: =TEXT(FIN_DATASET[[#This Row],[Date]],"mmmm") -> January | D8: =IF(FIN_RAW[[#This Row],[VALOR (IN)]]>0, "Income",IF(FIN_RAW[[#This Row],[VALOR (OUT)]]>0, "Expense", "Check")) -> Income | E8: =_xlfn.XLOOKUP(FIN_DATASET[[#This Row],[Method]],CATEGORY_MAP[CUENTA_IN],CATEGORY_MAP[Category]) -> Scholarships | F8: =_xlfn.XLOOKUP(FIN_DATASET[[#This Row],[Account]],CATEGORY_MAP[CUENTA_OUT],CATEGORY_MAP[Subcategory]) -> Monthly Fee | G8: =IF(OR(FIN_RAW[[#This Row],[CONCEPTO]]=0,FIN_RAW[[#This Row],[CONCEPTO]]=""),"",FIN_RAW[[#This Row],[CONCEPTO]]) -> Beca 2do Hermanos (20%) (ENE) | H8: =IF(FIN_DATASET[[#This Row],[Type]]="Income", FIN_RAW[[#This Row],[VALOR (IN)]], -FIN_RAW[[#This Row],[VALOR (OUT)]]) -> 20000 | I8: =FIN_RAW[[#This Row],[CUENTA (IN)]] -> Becas | J8: =FIN_RAW[[#This Row],[CUENTA (OUT)]] -> Mensualidad | K8: =IF(OR(FIN_RAW[[#This Row],[CLIENTE]]=0,FIN_RAW[[#This Row],[CLIENTE]]=" "),"",FIN_RAW[[#This Row],[CLIENTE]]) -> Luis Fernando Zea Sanabria | L8: =IF(OR(FIN_RAW[[#This Row],[DEPORTISTA]]=0,FIN_RAW[[#This Row],[DEPORTISTA]]=""),"",FIN_RAW[[#This Row],[DEPORTISTA]]) -> Jacobo Zea Osorio | M8: =IF(FIN_DATASET[[#This Row],[Method]]="Efectivo",1,0) -> 0 | N8: =IF(FIN_DATASET[[#This Row],[Method]]="Efectivo",FIN_DATASET[[#This Row],[Amount]],0) -> 0 | O8: =IF(FIN_DATASET[[#This Row],[Method]]="CxC",1,0) -> 0 | P8: =IF(FIN_DATASET[[#This Row],[Method]]="CxC",FIN_DATASET[[#This Row],[Amount]],0) -> 0 | Q8: =IF(OR(FIN_DATASET[[#This Row],[Account]]="CxP",FIN_DATASET[[#This Row],[Account]]="CxP (Liga)",FIN_DATASET[[#This Row],[Account]]="CxP (Terceros)"),1,0) -> 0 | R8: =IF(FIN_DATASET[[#This Row],[AP_Flag]]=1,FIN_DATASET[[#This Row],[Amount]],0) -> 0
A9: =FIN_RAW[[#This Row],[FECHA]] -> 43832 | B9: =YEAR(FIN_DATASET[[#This Row],[Date]]) -> 2020 | C9: =TEXT(FIN_DATASET[[#This Row],[Date]],"mmmm") -> January | D9: =IF(FIN_RAW[[#This Row],[VALOR (IN)]]>0, "Income",IF(FIN_RAW[[#This Row],[VALOR (OUT)]]>0, "Expense", "Check")) -> Income | E9: =_xlfn.XLOOKUP(FIN_DATASET[[#This Row],[Method]],CATEGORY_MAP[CUENTA_IN],CATEGORY_MAP[Category]) -> Cash | F9: =_xlfn.XLOOKUP(FIN_DATASET[[#This Row],[Account]],CATEGORY_MAP[CUENTA_OUT],CATEGORY_MAP[Subcategory]) -> Enrollment Fees | G9: =IF(OR(FIN_RAW[[#This Row],[CONCEPTO]]=0,FIN_RAW[[#This Row],[CONCEPTO]]=""),"",FIN_RAW[[#This Row],[CONCEPTO]]) -> Pago Matricula 100% | H9: =IF(FIN_DATASET[[#This Row],[Type]]="Income", FIN_RAW[[#This Row],[VALOR (IN)]], -FIN_RAW[[#This Row],[VALOR (OUT)]]) -> 100000 | I9: =FIN_RAW[[#This Row],[CUENTA (IN)]] -> Efectivo | J9: =FIN_RAW[[#This Row],[CUENTA (OUT)]] -> Matricula | K9: =IF(OR(FIN_RAW[[#This Row],[CLIENTE]]=0,FIN_RAW[[#This Row],[CLIENTE]]=" "),"",FIN_RAW[[#This Row],[CLIENTE]]) -> Luis Fernando Zea Sanabria | L9: =IF(OR(FIN_RAW[[#This Row],[DEPORTISTA]]=0,FIN_RAW[[#This Row],[DEPORTISTA]]=""),"",FIN_RAW[[#This Row],[DEPORTISTA]]) -> Jacobo Zea Osorio | M9: =IF(FIN_DATASET[[#This Row],[Method]]="Efectivo",1,0) -> 1 | N9: =IF(FIN_DATASET[[#This Row],[Method]]="Efectivo",FIN_DATASET[[#This Row],[Amount]],0) -> 100000 | O9: =IF(FIN_DATASET[[#This Row],[Method]]="CxC",1,0) -> 0 | P9: =IF(FIN_DATASET[[#This Row],[Method]]="CxC",FIN_DATASET[[#This Row],[Amount]],0) -> 0 | Q9: =IF(OR(FIN_DATASET[[#This Row],[Account]]="CxP",FIN_DATASET[[#This Row],[Account]]="CxP (Liga)",FIN_DATASET[[#This Row],[Account]]="CxP (Terceros)"),1,0) -> 0 | R9: =IF(FIN_DATASET[[#This Row],[AP_Flag]]=1,FIN_DATASET[[#This Row],[Amount]],0) -> 0
A10: =FIN_RAW[[#This Row],[FECHA]] -> 43832 | B10: =YEAR(FIN_DATASET[[#This Row],[Date]]) -> 2020 | C10: =TEXT(FIN_DATASET[[#This Row],[Date]],"mmmm") -> January | D10: =IF(FIN_RAW[[#This Row],[VALOR (IN)]]>0, "Income",IF(FIN_RAW[[#This Row],[VALOR (OUT)]]>0, "Expense", "Check")) -> Income | E10: =_xlfn.XLOOKUP(FIN_DATASET[[#This Row],[Method]],CATEGORY_MAP[CUENTA_IN],CATEGORY_MAP[Category]) -> Cash | F10: =_xlfn.XLOOKUP(FIN_DATASET[[#This Row],[Account]],CATEGORY_MAP[CUENTA_OUT],CATEGORY_MAP[Subcategory]) -> Monthly Fee | G10: =IF(OR(FIN_RAW[[#This Row],[CONCEPTO]]=0,FIN_RAW[[#This Row],[CONCEPTO]]=""),"",FIN_RAW[[#This Row],[CONCEPTO]]) -> Pago Mensualidad (ENE) | H10: =IF(FIN_DATASET[[#This Row],[Type]]="Income", FIN_RAW[[#This Row],[VALOR (IN)]], -FIN_RAW[[#This Row],[VALOR (OUT)]]) -> 80000 | I10: =FIN_RAW[[#This Row],[CUENTA (IN)]] -> Efectivo | J10: =FIN_RAW[[#This Row],[CUENTA (OUT)]] -> Mensualidad | K10: =IF(OR(FIN_RAW[[#This Row],[CLIENTE]]=0,FIN_RAW[[#This Row],[CLIENTE]]=" "),"",FIN_RAW[[#This Row],[CLIENTE]]) -> Luis Fernando Zea Sanabria | L10: =IF(OR(FIN_RAW[[#This Row],[DEPORTISTA]]=0,FIN_RAW[[#This Row],[DEPORTISTA]]=""),"",FIN_RAW[[#This Row],[DEPORTISTA]]) -> Jacobo Zea Osorio | M10: =IF(FIN_DATASET[[#This Row],[Method]]="Efectivo",1,0) -> 1 | N10: =IF(FIN_DATASET[[#This Row],[Method]]="Efectivo",FIN_DATASET[[#This Row],[Amount]],0) -> 80000 | O10: =IF(FIN_DATASET[[#This Row],[Method]]="CxC",1,0) -> 0 | P10: =IF(FIN_DATASET[[#This Row],[Method]]="CxC",FIN_DATASET[[#This Row],[Amount]],0) -> 0 | Q10: =IF(OR(FIN_DATASET[[#This Row],[Account]]="CxP",FIN_DATASET[[#This Row],[Account]]="CxP (Liga)",FIN_DATASET[[#This Row],[Account]]="CxP (Terceros)"),1,0) -> 0 | R10: =IF(FIN_DATASET[[#This Row],[AP_Flag]]=1,FIN_DATASET[[#This Row],[Amount]],0) -> 0
A11: =FIN_RAW[[#This Row],[FECHA]] -> 43832 | B11: =YEAR(FIN_DATASET[[#This Row],[Date]]) -> 2020 | C11: =TEXT(FIN_DATASET[[#This Row],[Date]],"mmmm") -> January | D11: =IF(FIN_RAW[[#This Row],[VALOR (IN)]]>0, "Income",IF(FIN_RAW[[#This Row],[VALOR (OUT)]]>0, "Expense", "Check")) -> Income | E11: =_xlfn.XLOOKUP(FIN_DATASET[[#This Row],[Method]],CATEGORY_MAP[CUENTA_IN],CATEGORY_MAP[Category]) -> Scholarships | F11: =_xlfn.XLOOKUP(FIN_DATASET[[#This Row],[Account]],CATEGORY_MAP[CUENTA_OUT],CATEGORY_MAP[Subcategory]) -> Monthly Fee | G11: =IF(OR(FIN_RAW[[#This Row],[CONCEPTO]]=0,FIN_RAW[[#This Row],[CONCEPTO]]=""),"",FIN_RAW[[#This Row],[CONCEPTO]]) -> Becas Resultados 2019 (100%) (ENE) | H11: =IF(FIN_DATASET[[#This Row],[Type]]="Income", FIN_RAW[[#This Row],[VALOR (IN)]], -FIN_RAW[[#This Row],[VALOR (OUT)]]) -> 150000 | I11: =FIN_RAW[[#This Row],[CUENTA (IN)]] -> Becas | J11: =FIN_RAW[[#This Row],[CUENTA (OUT)]] -> Mensualidad | K11: =IF(OR(FIN_RAW[[#This Row],[CLIENTE]]=0,FIN_RAW[[#This Row],[CLIENTE]]=" "),"",FIN_RAW[[#This Row],[CLIENTE]]) -> Omar Osorio Valencia | L11: =IF(OR(FIN_RAW[[#This Row],[DEPORTISTA]]=0,FIN_RAW[[#This Row],[DEPORTISTA]]=""),"",FIN_RAW[[#This Row],[DEPORTISTA]]) -> Juan Camilo Osorio Mendoza | M11: =IF(FIN_DATASET[[#This Row],[Method]]="Efectivo",1,0) -> 0 | N11: =IF(FIN_DATASET[[#This Row],[Method]]="Efectivo",FIN_DATASET[[#This Row],[Amount]],0) -> 0 | O11: =IF(FIN_DATASET[[#This Row],[Method]]="CxC",1,0) -> 0 | P11: =IF(FIN_DATASET[[#This Row],[Method]]="CxC",FIN_DATASET[[#This Row],[Amount]],0) -> 0 | Q11: =IF(OR(FIN_DATASET[[#This Row],[Account]]="CxP",FIN_DATASET[[#This Row],[Account]]="CxP (Liga)",FIN_DATASET[[#This Row],[Account]]="CxP (Terceros)"),1,0) -> 0 | R11: =IF(FIN_DATASET[[#This Row],[AP_Flag]]=1,FIN_DATASET[[#This Row],[Amount]],0) -> 0
A12: =FIN_RAW[[#This Row],[FECHA]] -> 43832 | B12: =YEAR(FIN_DATASET[[#This Row],[Date]]) -> 2020 | C12: =TEXT(FIN_DATASET[[#This Row],[Date]],"mmmm") -> January | D12: =IF(FIN_RAW[[#This Row],[VALOR (IN)]]>0, "Income",IF(FIN_RAW[[#This Row],[VALOR (OUT)]]>0, "Expense", "Check")) -> Expense | E12: =_xlfn.XLOOKUP(FIN_DATASET[[#This Row],[Method]],CATEGORY_MAP[CUENTA_IN],CATEGORY_MAP[Category]) -> Cash | F12: =_xlfn.XLOOKUP(FIN_DATASET[[#This Row],[Account]],CATEGORY_MAP[CUENTA_OUT],CATEGORY_MAP[Subcategory]) -> Athlete Support | G12: =IF(OR(FIN_RAW[[#This Row],[CONCEPTO]]=0,FIN_RAW[[#This Row],[CONCEPTO]]=""),"",FIN_RAW[[#This Row],[CONCEPTO]]) -> Apoyo Gimnasio (Crossfit) (ENE) | H12: =IF(FIN_DATASET[[#This Row],[Type]]="Income", FIN_RAW[[#This Row],[VALOR (IN)]], -FIN_RAW[[#This Row],[VALOR (OUT)]]) -> -50000 | I12: =FIN_RAW[[#This Row],[CUENTA (IN)]] -> Efectivo | J12: =FIN_RAW[[#This Row],[CUENTA (OUT)]] -> Apoyo Deportistas | K12: =IF(OR(FIN_RAW[[#This Row],[CLIENTE]]=0,FIN_RAW[[#This Row],[CLIENTE]]=" "),"",FIN_RAW[[#This Row],[CLIENTE]]) -> Víctor Manuel Duque Yepes | L12: =IF(OR(FIN_RAW[[#This Row],[DEPORTISTA]]=0,FIN_RAW[[#This Row],[DEPORTISTA]]=""),"",FIN_RAW[[#This Row],[DEPORTISTA]]) -> Juan Manuel Duque Pinto | M12: =IF(FIN_DATASET[[#This Row],[Method]]="Efectivo",1,0) -> 1 | N12: =IF(FIN_DATASET[[#This Row],[Method]]="Efectivo",FIN_DATASET[[#This Row],[Amount]],0) -> -50000 | O12: =IF(FIN_DATASET[[#This Row],[Method]]="CxC",1,0) -> 0 | P12: =IF(FIN_DATASET[[#This Row],[Method]]="CxC",FIN_DATASET[[#This Row],[Amount]],0) -> 0 | Q12: =IF(OR(FIN_DATASET[[#This Row],[Account]]="CxP",FIN_DATASET[[#This Row],[Account]]="CxP (Liga)",FIN_DATASET[[#This Row],[Account]]="CxP (Terceros)"),1,0) -> 0 | R12: =IF(FIN_DATASET[[#This Row],[AP_Flag]]=1,FIN_DATASET[[#This Row],[Amount]],0) -> 0
A13: =FIN_RAW[[#This Row],[FECHA]] -> 43832 | B13: =YEAR(FIN_DATASET[[#This Row],[Date]]) -> 2020 | C13: =TEXT(FIN_DATASET[[#This Row],[Date]],"mmmm") -> January | D13: =IF(FIN_RAW[[#This Row],[VALOR (IN)]]>0, "Income",IF(FIN_RAW[[#This Row],[VALOR (OUT)]]>0, "Expense", "Check")) -> Income | E13: =_xlfn.XLOOKUP(FIN_DATASET[[#This Row],[Method]],CATEGORY_MAP[CUENTA_IN],CATEGORY_MAP[Category]) -> Cash | F13: =_xlfn.XLOOKUP(FIN_DATASET[[#This Row],[Account]],CATEGORY_MAP[CUENTA_OUT],CATEGORY_MAP[Subcategory]) -> Enrollment Fees | G13: =IF(OR(FIN_RAW[[#This Row],[CONCEPTO]]=0,FIN_RAW[[#This Row],[CONCEPTO]]=""),"",FIN_RAW[[#This Row],[CONCEPTO]]) -> Pago Matricula 100% | H13: =IF(FIN_DATASET[[#This Row],[Type]]="Income", FIN_RAW[[#This Row],[VALOR (IN)]], -FIN_RAW[[#This Row],[VALOR (OUT)]]) -> 100000 | I13: =FIN_RAW[[#This Row],[CUENTA (IN)]] -> Efectivo | J13: =FIN_RAW[[#This Row],[CUENTA (OUT)]] -> Matricula | K13: =IF(OR(FIN_RAW[[#This Row],[CLIENTE]]=0,FIN_RAW[[#This Row],[CLIENTE]]=" "),"",FIN_RAW[[#This Row],[CLIENTE]]) -> Víctor Manuel Duque Yepes | L13: =IF(OR(FIN_RAW[[#This Row],[DEPORTISTA]]=0,FIN_RAW[[#This Row],[DEPORTISTA]]=""),"",FIN_RAW[[#This Row],[DEPORTISTA]]) -> Juan Manuel Duque Pinto | M13: =IF(FIN_DATASET[[#This Row],[Method]]="Efectivo",1,0) -> 1 | N13: =IF(FIN_DATASET[[#This Row],[Method]]="Efectivo",FIN_DATASET[[#This Row],[Amount]],0) -> 100000 | O13: =IF(FIN_DATASET[[#This Row],[Method]]="CxC",1,0) -> 0 | P13: =IF(FIN_DATASET[[#This Row],[Method]]="CxC",FIN_DATASET[[#This Row],[Amount]],0) -> 0 | Q13: =IF(OR(FIN_DATASET[[#This Row],[Account]]="CxP",FIN_DATASET[[#This Row],[Account]]="CxP (Liga)",FIN_DATASET[[#This Row],[Account]]="CxP (Terceros)"),1,0) -> 0 | R13: =IF(FIN_DATASET[[#This Row],[AP_Flag]]=1,FIN_DATASET[[#This Row],[Amount]],0) -> 0
... A2884: =FIN_RAW[[#This Row],[FECHA]] -> 46022 | B2884: =YEAR(FIN_DATASET[[#This Row],[Date]]) -> 2025 | C2884: =TEXT(FIN_DATASET[[#This Row],[Date]],"mmmm") -> December | D2884: =IF(FIN_RAW[[#This Row],[VALOR (IN)]]>0, "Income",IF(FIN_RAW[[#This Row],[VALOR (OUT)]]>0, "Expense", "Check")) -> Expense | E2884: =_xlfn.XLOOKUP(FIN_DATASET[[#This Row],[Method]],CATEGORY_MAP[CUENTA_IN],CATEGORY_MAP[Category]) -> Accounts Receivable | F2884: =_xlfn.XLOOKUP(FIN_DATASET[[#This Row],[Account]],CATEGORY_MAP[CUENTA_OUT],CATEGORY_MAP[Subcategory]) -> Scholarships | G2884: =IF(OR(FIN_RAW[[#This Row],[CONCEPTO]]=0,FIN_RAW[[#This Row],[CONCEPTO]]=""),"",FIN_RAW[[#This Row],[CONCEPTO]]) -> CxC Incobrable (Perdida) | H2884: =IF(FIN_DATASET[[#This Row],[Type]]="Income", FIN_RAW[[#This Row],[VALOR (IN)]], -FIN_RAW[[#This Row],[VALOR (OUT)]]) -> -1860000 | I2884: =FIN_RAW[[#This Row],[CUENTA (IN)]] -> CxC | J2884: =FIN_RAW[[#This Row],[CUENTA (OUT)]] -> Becas | K2884: =IF(OR(FIN_RAW[[#This Row],[CLIENTE]]=0,FIN_RAW[[#This Row],[CLIENTE]]=" "),"",FIN_RAW[[#This Row],[CLIENTE]]) -> Diana Gómez Herrera | L2884: =IF(OR(FIN_RAW[[#This Row],[DEPORTISTA]]=0,FIN_RAW[[#This Row],[DEPORTISTA]]=""),"",FIN_RAW[[#This Row],[DEPORTISTA]]) -> Juan Manuel López Gómez | M2884: =IF(FIN_DATASET[[#This Row],[Method]]="Efectivo",1,0) -> 0 | N2884: =IF(FIN_DATASET[[#This Row],[Method]]="Efectivo",FIN_DATASET[[#This Row],[Amount]],0) -> 0 | O2884: =IF(FIN_DATASET[[#This Row],[Method]]="CxC",1,0) -> 1 | P2884: =IF(FIN_DATASET[[#This Row],[Method]]="CxC",FIN_DATASET[[#This Row],[Amount]],0) -> -1860000 | Q2884: =IF(OR(FIN_DATASET[[#This Row],[Account]]="CxP",FIN_DATASET[[#This Row],[Account]]="CxP (Liga)",FIN_DATASET[[#This Row],[Account]]="CxP (Terceros)"),1,0) -> 0 | R2884: =IF(FIN_DATASET[[#This Row],[AP_Flag]]=1,FIN_DATASET[[#This Row],[Amount]],0) -> 0

Sheet Pivot_Financials
B4: Sum of Amount | C4: Column Labels | I4: Type | J4: Income | N4: Row Labels | O4: Sum of Cash Amount
B5: Row Labels | C5: Income | D5: Expense | E5: Profit | N5: 2020 | O5: 699469
B6: 2020 | C6: 15107020 | D6: -12306187 | E6: 2800833 | I6: Row Labels | J6: Sum of Amount | N6: January | O6: 1772000
B7: January | C7: 5222020 | D7: -1228000 | E7: 3994020 | I7: Accounts Receivable | J7: 14980000 | N7: February | O7: -401500
B8: February | C8: 1160000 | D8: -1071500 | E8: 88500 | I8: Adjustments | J8: 927500 | N8: March | O8: -185000
B9: March | C9: 605000 | D9: -545000 | E9: 60000 | I9: Cash | J9: 2.0489867e+08 | N9: April | O9: 100000
B10: April | C10: 495000 | D10: -200000 | E10: 295000 | I10: Profit 2020 | J10: 1177020 | N10: May | O10: 400000
B11: May | C11: 720000 | D11: -200000 | E11: 520000 | I11: Profit 2021 | J11: 25469 | N11: June | O11: -450000
B12: June | C12: 420000 | D12: -750000 | E12: -330000 | I12: Profit 2022 | J12: 1355469 | N12: July | O12: -280000
B13: July | C13: 630000 | D13: -790000 | E13: -160000 | I13: Profit 2024 | J13: 976000 | N13: August | O13: 280000
B14: August | C14: 600000 | D14: -200000 | E14: 400000 | I14: Profit 2025 | J14: 11094500 | N14: September | O14: 100000
B15: September | C15: 420000 | D15: -200000 | E15: 220000 | I15: Scholarships | J15: 55896000 | N15: October | O15: 595000
B16: October | C16: 1135000 | D16: -420000 | E16: 715000 | I16: Sports Equipment | J16: 16733411 | N16: November | O16: 410000
B17: November | C17: 1800000 | D17: -990000 | E17: 810000 | I17: Uniform Sales | J17: 500000 | N17: December | O17: -1641031
B18: December | C18: 1900000 | D18: -5711687 | E18: -3811687 | I18: Grand Total | J18: 308564038 | N18: 2021 | O18: 164000
B19: 2021 | C19: 43311676 | D19: -31873094 | E19: 11438582 | N19: January | O19: 2703469
B20: January | C20: 9942676 | D20: -1025469 | E20: 8917207 | N20: February | O20: -298800
B21: February | C21: 3425000 | D21: -5217456 | E21: -1792456 | N21: March | O21: -1590300
B22: March | C22: 3195000 | D22: -4095800 | E22: -900800 | N22: April | O22: 1199321
B23: April | C23: 5133000 | D23: -3244179 | E23: 1888821 | I23: Type | J23: Expense | N23: May | O23: 604000
B24: May | C24: 2495000 | D24: -1300000 | E24: 1195000 | N24: June | O24: -953500
B25: June | C25: 3728000 | D25: -4034000 | E25: -306000 | I25: Row Labels | J25: Sum of Amount | N25: July | O25: 1329000
B26: July | C26: 4763000 | D26: -2786500 | E26: 1976500 | I26: Account Adjustments | J26: -651469.41 | N26: August | O26: 432500
B27: August | C27: 2980000 | D27: -1900000 | E27: 1080000 | I27: Accounts Payable | J27: -2570656 | N27: September | O27: 456000
B28: September | C28: 3122500 | D28: -1900000 | E28: 1222500 | I28: Accounts Payable – League | J28: -3225000 | N28: October | O28: 62000
B29: October | C29: 2852500 | D29: -1900000 | E29: 952500 | I29: Accounts Payable – Third Parties | J29: -771000 | N29: November | O29: -1806000
B30: November | C30: 915000 | D30: -2196000 | E30: -1281000 | I30: Advertising | J30: -385000 | N30: December | O30: -1973690
B31: December | C31: 760000 | D31: -2273690 | E31: -1513690 | I31: Athlete Support | J31: -3347800 | N31: 2022 | O31: -477531
B32: 2022 | C32: 53887489 | D32: -37960531 | E32: 15926958 | I32: Capital | J32: -5706000 | N32: January | O32: 4050000
B33: January | C33: 10995489 | D33: -2153000 | E33: 8842489 | I33: Cash | J33: -503000 | N33: February | O33: -1388000
B34: February | C34: 3780000 | D34: -4214000 | E34: -434000 | I34: Coach Support | J34: -2200000 | N34: March | O34: -387000
B35: March | C35: 4165000 | D35: -3620000 | E35: 545000 | I35: Financial Charges | J35: -1293179 | N35: April | O35: 178000
B36: April | C36: 4210000 | D36: -3100000 | E36: 1110000 | I36: Monthly Fee | J36: -16000 | N36: May | O36: 1078000
B37: May | C37: 4510000 | D37: -2500000 | E37: 2010000 | I37: Operating Expenses | J37: -10821721 | N37: June | O37: -330000
B38: June | C38: 4757000 | D38: -4035000 | E38: 722000 | I38: Payroll | J38: -142175000 | N38: July | O38: 400000
B39: July | C39: 3865000 | D39: -2500000 | E39: 1365000 | I39: Refunds | J39: -290000 | N39: August | O39: 185000
B40: August | C40: 3545000 | D40: -2450000 | E40: 1095000 | I40: Rent | J40: -8418200 | N40: September | O40: -2400000
B41: September | C41: 3610000 | D41: -5100000 | E41: -1490000 | I41: Scholarships | J41: -3877000 | N41: October | O41: 1507000
B42: October | C42: 3385000 | D42: -808000 | E42: 2577000 | I42: Sports Equipment | J42: -5273207 | N42: November | O42: -760000
B43: November | C43: 3545000 | D43: -3000000 | E43: 545000 | I43: Sports Expenses | J43: -2147280 | N43: December | O43: -2610531
...

Sheet KPIs
A1: KPI - General Financial | B1: Type | C1: Income | E1: Type | F1: Expense
B3: Sum of Amount | E3: Sum of Amount
A4: Total Income | B4: 308564038 | D4: Total Expense | E4: -2.1945101e+08
A6: Net Profit | B6: =GETPIVOTDATA("Amount",$B$3)+GETPIVOTDATA("Amount",$E$3) -> 89113026
A8: Average Monthly Income | B8: =GETPIVOTDATA("Amount",$B$3)/12 -> 25713670 | D8: Average Monthly Expense | E8: =GETPIVOTDATA("Amount",$E$4)/12 -> -18287584
A10: Income Categories (Count) | B10: =COUNTA(_xlfn.UNIQUE(FIN_DATASET[Category])) -> 18 | D10: Expense Subcategories (Count) | E10: =COUNTA(_xlfn.UNIQUE(FIN_DATASET[Subcategory])) -> 28
A12: KPI - Cash Flow | B12: Cash Flag | C12: 1 | E12: Cash Flag | F12: 1
B13: Type | C13: Income | E13: Type | F13: Expense
B15: Sum of Cash Amount | E15: Sum of Cash Amount
A16: Cash In (Total) | B16: 2.0489867e+08 | D16: Cash Out (Total) | E16: -199867231
A18: Net Cash Flow | B18: =GETPIVOTDATA("Cash Amount",$B$15)+GETPIVOTDATA("Cash Amount",$E$15) -> 5031437.6 | D18: Cash Transactions Count | E18: =COUNTIFS(FIN_DATASET[Cash Flag],1) -> 2213
A20: Cash Income % | B20: =GETPIVOTDATA("Cash Amount",$B$15) / GETPIVOTDATA("Amount",$B$3) -> 0.66403937 | D20: Cash Expense % | E20: =GETPIVOTDATA("Cash Amount",$E$15) / GETPIVOTDATA("Amount",$E$3) -> 0.91076012
A22: KPI - AR & AP | B22: AR_Flag | C22: 1 | E22: AP_Flag | F22: 1
B24: Sum of AR_Amount | E24: Sum of AP_Amount
A25: Total Accounts Receivable | B25: 10584000 | D25: Total Accounts Payable | E25: -3889000
A27: Clients with Debt (count) | B27: {=COUNTA(_xlfn.UNIQUE(_xlfn._xlws.FILTER(FIN_DATASET[Client], FIN_DATASET[AR_Amount]<>0)))} -> 21 | D27: Payables Items Count | E27: =COUNTIF(FIN_DATASET[AP_Flag],1) -> 6
A29: Average Debt per Client | B29: =IF(B27=0,0,GETPIVOTDATA("AR_Amount",$B$24)/B27) -> 504000
A31: Biggest Debtor Amount | B31: =MAX(FIN_DATASET[AR_Amount]) -> 1020000 | D31: Largest Payable | E31: =-MIN(FIN_DATASET[AP_Amount]) -> 2570656
A33: Total AR Transactions | B33: =COUNTIF(FIN_DATASET[AR_Flag],1) -> 94 | D33: CxP Categories | E33: {=COUNTA(_xlfn.UNIQUE(_xlfn._xlws.FILTER(FIN_DATASET[Account], FIN_DATASET[AP_Flag]=1)))} -> 3

Sheet Dashboard
B2: CLUB TORNADO — FINANCIAL DASHBOARD (2020–2025)
B6: INCOME | C6: EXPENSES | D6: NET PROFIT | E6: CASH IN | F6: CASH OUT | G6: ACCOUNT RECEIVABLE | H6: ACCOUNT PAYABLE
B8: =GETPIVOTDATA("Amount",KPIs!$B$3) -> 308564038 | C8: =GETPIVOTDATA("Amount",KPIs!$E$3) -> -2.1945101e+08 | D8: =KPIs!B6 -> 89113026 | E8: =GETPIVOTDATA("Cash Amount",KPIs!$B$15) -> 2.0489867e+08 | F8: =GETPIVOTDATA("Cash Amount",KPIs!$E$15) -> -199867231 | G8: =GETPIVOTDATA("AR_Amount",KPIs!$B$24) -> 10584000 | H8: =GETPIVOTDATA("AP_Amount",KPIs!$E$24) -> -3889000
